Workbook

Sheet START HERE
A1: EIP ACCEPTANCE TEST CAMPAIGN — 5th-year projects tested by 3rd-year students
A2: 1 — WHAT YOU HAVE TO DO
A3: Run every scenario in your project tab by hand, exactly as written, and record what actually happened in the RESULT, Severity, Feedback, Tester and Date columns. A scenario passes only if every expected result is obtained — if you did not see it work with your own eyes, it did not work.
A4: 2 — THE RESULT VALUES
A5: Value | B5: Use it when
A6: OK | B6: Every expected result was obtained, in order, without error. Cosmetic differences do not fail a scenario — note them in Feedback and still mark OK.
A7: Partial | B7: The feature runs but at least one expected result was not obtained. Say exactly which one in Feedback.
A8: KO | B8: The feature is there but wrong: crash, wrong output, data loss, corrupted result, expected behaviour missing.
A9: Blocked | B9: You could not run the scenario at all — a prerequisite could not be met, an earlier scenario failed, the app will not start, the feature is unreachable.
A10: N/A | B10: The scenario genuinely does not apply to you: no NVIDIA GPU, no controller, the team declared it not testable this cycle. Always say why in Feedback.
A11: Not tested | B11: The starting value. Nothing has been done yet. Leave none of these behind at the end of your run.
A12: 3 — THE FIVE PROJECTS
A13: Project | B13: What it is | C13: Where to get it | D13: Scenarios | E13: Tab
A14: Eclyps | B14: Eclyps is a 3D non-Euclidean puzzle game taking place in a cel-shading styled world with a unique storyline. The purpose of our game is to make people experience mental madness perception while solving enigmas containing unusual perspectives and illusions. Inspired by games like Exit 8 or Superliminal, It challenges and forces players to think outside the box while exposing them more and more through each level to the symptoms of madness. | C14: https://eclypswebsite.netlify.app | D14: 45 total 15 critical | E14: Eclyps
A15: Dissonance | B15: Desktop app that applies imperceptible adversarial perturbations to audio so it can’t be exploited for AI training. Versions under test: UI v0.1.1 with bundled core v0.0.5 (branch dev). | C15: https://github.com/Dissonance-Eip/ui/releases/latest | D15: 56 total 27 critical | E15: Dissonance
A16: Pathly | B16: Pathly is a social network designed for travelers who love to plan, share, and explore It’s the perfect platform to create, collaborate, and customize trip itineraries with friends, family, or fellow adventurers. Discover trending destinations, get personalized recommendations, and share your travel experiences with a vibrant community of globetrotters. | C16: https://pathly-web-brown.vercel.app/ | D16: 36 total 26 critical | E16: Pathly
A17: Horus | B17: Version under test: Horus Beta 0.1.0. The archive carries the installer, the source the stack builds from, the desktop apps and the test corpus. No repository access is needed. | C17: https://epitechfr-my.sharepoint.com/:u:/g/personal/loup_marquez_epitech_eu/IQDSYS6FbbXXR50eb-HXaqiWAZdwJ_LRXc47EHymear3qyQ?e=8wllsu | D17: 37 total 25 critical | E17: Horus
A18: FAS | B18: FAS is a LegalTech solution that streamlines contract management, allowing users to create, fill, sign, and manage contracts anytime, anywhere. It uniquely supports and authenticates verbal agreements, a feature not found in other software. FAS also facilitates written agreements, leveraging AI for audio-based contract filling, summaries and more. | C18: https://fas-ai.net | D18: 44 total 19 critical | E18: FAS
A19: TOTAL | D19: 218 scenarios
A20: ECLYPS — setup & access (tab "Eclyps" · 45 scenarios)
A21: Access points
A22: Access point | B22: URL / command | C22: Notes
A23: Game download | B23: https://eclypswebsite.netlify.app
A24: Accounts
A25: Account type | B25: Identifier | C25: Password
A26: UE5 (Epic Games User) | B26: user@epicgames.com | C26: Epicpwd
A27: Steam User | B27: user@steam.com | C27: Steampwd
A28: DISSONANCE — setup & access (tab "Dissonance" · 56 scenarios)
A29: Test environment | B29: macOS on Apple Silicon (the release ships arm64 only), Windows 10/11 x64, or x64 Linux with AppImage support. Audio output: headphones strongly recommended — several scenarios are listening tests.
A30: Access points
A31: Access point | B31: URL / command | C31: Notes
A32: App download (all platforms) | C32: macOS .dmg (Apple Silicon only) · Windows .exe · Linux .AppImage (chmod +x first). This installer is the whole deliverable — nothing else needs building.
A33: Source repository (reference) | B33: https://github.com/Dissonance-Eip/ui | C33: For reference only — testers work from the installer above. Branch under test: dev.
A34: Accounts
A35: Account type | B35: Identifier | C35: Password
A36: None required | B36: — | C36: Dissonance is a fully offline desktop app: no sign-up, no login, no server.
A37: Test data
A38: All test audio files come from the team’s Appendix ZIP.
A39: File / item | B39: Description
A40: atp_stereo_44k.wav | B40: 30 s, 44.1 kHz, 16-bit stereo, all seven tags filled. Main file for the UI scenarios.
...

Sheet Dashboard
A1: CAMPAIGN DASHBOARD — live, updates itself as the project tabs are filled in
A3: Project | B3: Scenarios | C3: Critical | D3: Not tested | E3: OK | F3: Partial | G3: KO | H3: Blocked | I3: N/A | J3: % tested | K3: % OK (of tested) | L3: Open defects
A5: Eclyps | B5: 45 | C5: =COUNTIF(Eclyps!$C$2:$C$46,"Critical feature") -> 15 | D5: =COUNTIF(Eclyps!$I$2:$I$46,"Not tested") -> 0 | E5: =COUNTIF(Eclyps!$I$2:$I$46,"OK") -> 21 | F5: =COUNTIF(Eclyps!$I$2:$I$46,"Partial") -> 1 | G5: =COUNTIF(Eclyps!$I$2:$I$46,"KO") -> 2 | H5: =COUNTIF(Eclyps!$I$2:$I$46,"Blocked") -> 0 | I5: =COUNTIF(Eclyps!$I$2:$I$46,"N/A") -> 21 | J5: =IF(B5=0,0,(B5-D5)/B5) -> 1 | K5: =IF((B5-D5-I5)=0,"—",E5/(B5-D5-I5)) -> 0.875 | L5: =F5+G5+H5 -> 3
A6: Dissonance | B6: 56 | C6: =COUNTIF(Dissonance!$C$2:$C$57,"Critical feature") -> 27 | D6: =COUNTIF(Dissonance!$I$2:$I$57,"Not tested") -> 0 | E6: =COUNTIF(Dissonance!$I$2:$I$57,"OK") -> 43 | F6: =COUNTIF(Dissonance!$I$2:$I$57,"Partial") -> 0 | G6: =COUNTIF(Dissonance!$I$2:$I$57,"KO") -> 0 | H6: =COUNTIF(Dissonance!$I$2:$I$57,"Blocked") -> 0 | I6: =COUNTIF(Dissonance!$I$2:$I$57,"N/A") -> 13 | J6: =IF(B6=0,0,(B6-D6)/B6) -> 1 | K6: =IF((B6-D6-I6)=0,"—",E6/(B6-D6-I6)) -> 1 | L6: =F6+G6+H6 -> 0
A7: Pathly | B7: 36 | C7: =COUNTIF(Pathly!$C$2:$C$37,"Critical feature") -> 26 | D7: =COUNTIF(Pathly!$I$2:$I$37,"Not tested") -> 0 | E7: =COUNTIF(Pathly!$I$2:$I$37,"OK") -> 30 | F7: =COUNTIF(Pathly!$I$2:$I$37,"Partial") -> 2 | G7: =COUNTIF(Pathly!$I$2:$I$37,"KO") -> 1 | H7: =COUNTIF(Pathly!$I$2:$I$37,"Blocked") -> 0 | I7: =COUNTIF(Pathly!$I$2:$I$37,"N/A") -> 3 | J7: =IF(B7=0,0,(B7-D7)/B7) -> 1 | K7: =IF((B7-D7-I7)=0,"—",E7/(B7-D7-I7)) -> 0.90909091 | L7: =F7+G7+H7 -> 3
A8: Horus | B8: 37 | C8: =COUNTIF(Horus!$C$2:$C$38,"Critical feature") -> 25 | D8: =COUNTIF(Horus!$I$2:$I$38,"Not tested") -> 0 | E8: =COUNTIF(Horus!$I$2:$I$38,"OK") -> 28 | F8: =COUNTIF(Horus!$I$2:$I$38,"Partial") -> 3 | G8: =COUNTIF(Horus!$I$2:$I$38,"KO") -> 6 | H8: =COUNTIF(Horus!$I$2:$I$38,"Blocked") -> 0 | I8: =COUNTIF(Horus!$I$2:$I$38,"N/A") -> 0 | J8: =IF(B8=0,0,(B8-D8)/B8) -> 1 | K8: =IF((B8-D8-I8)=0,"—",E8/(B8-D8-I8)) -> 0.75675676 | L8: =F8+G8+H8 -> 9
A9: FAS | B9: 44 | C9: =COUNTIF(FAS!$C$2:$C$45,"Critical feature") -> 19 | D9: =COUNTIF(FAS!$I$2:$I$45,"Not tested") -> 0 | E9: =COUNTIF(FAS!$I$2:$I$45,"OK") -> 26 | F9: =COUNTIF(FAS!$I$2:$I$45,"Partial") -> 3 | G9: =COUNTIF(FAS!$I$2:$I$45,"KO") -> 1 | H9: =COUNTIF(FAS!$I$2:$I$45,"Blocked") -> 0 | I9: =COUNTIF(FAS!$I$2:$I$45,"N/A") -> 14 | J9: =IF(B9=0,0,(B9-D9)/B9) -> 1 | K9: =IF((B9-D9-I9)=0,"—",E9/(B9-D9-I9)) -> 0.86666667 | L9: =F9+G9+H9 -> 4
A10: TOTAL | B10: =SUM(B5:B9) -> 218 | C10: =SUM(C5:C9) -> 112 | D10: =SUM(D5:D9) -> 0 | E10: =SUM(E5:E9) -> 148 | F10: =SUM(F5:F9) -> 9 | G10: =SUM(G5:G9) -> 10 | H10: =SUM(H5:H9) -> 0 | I10: =SUM(I5:I9) -> 51 | J10: =IF(B10=0,0,(B10-D10)/B10) -> 1 | K10: =IF((B10-D10-I10)=0,"—",E10/(B10-D10-I10)) -> 0.88622754 | L10: =SUM(L5:L9) -> 19
A12: Open defects = Partial + KO + Blocked. "% OK (of tested)" excludes rows marked N/A. All figures recalculate automatically — nothing here is typed by hand.
A14: CRITICAL FEATURES ONLY — the scenarios that decide whether the product works at all
A15: Project | B15: Critical | C15: Not tested | D15: OK | E15: Partial | F15: KO | G15: Blocked | H15: N/A | I15: % critical tested | J15: % critical OK
A16: Eclyps | B16: =COUNTIF(Eclyps!$C$2:$C$46,"Critical feature") -> 15 | C16: =COUNTIFS(Eclyps!$C$2:$C$46,"Critical feature",Eclyps!$I$2:$I$46,"Not tested") -> 0 | D16: =COUNTIFS(Eclyps!$C$2:$C$46,"Critical feature",Eclyps!$I$2:$I$46,"OK") -> 11 | E16: =COUNTIFS(Eclyps!$C$2:$C$46,"Critical feature",Eclyps!$I$2:$I$46,"Partial") -> 1 | F16: =COUNTIFS(Eclyps!$C$2:$C$46,"Critical feature",Eclyps!$I$2:$I$46,"KO") -> 0 | G16: =COUNTIFS(Eclyps!$C$2:$C$46,"Critical feature",Eclyps!$I$2:$I$46,"Blocked") -> 0 | H16: =COUNTIFS(Eclyps!$C$2:$C$46,"Critical feature",Eclyps!$I$2:$I$46,"N/A") -> 3 | I16: =IF(B16=0,0,(B16-C16)/B16) -> 1 | J16: =IF((B16-C16-H16)=0,"—",D16/(B16-C16-H16)) -> 0.91666667
A17: Dissonance | B17: =COUNTIF(Dissonance!$C$2:$C$57,"Critical feature") -> 27 | C17: =COUNTIFS(Dissonance!$C$2:$C$57,"Critical feature",Dissonance!$I$2:$I$57,"Not tested") -> 0 | D17: =COUNTIFS(Dissonance!$C$2:$C$57,"Critical feature",Dissonance!$I$2:$I$57,"OK") -> 21 | E17: =COUNTIFS(Dissonance!$C$2:$C$57,"Critical feature",Dissonance!$I$2:$I$57,"Partial") -> 0 | F17: =COUNTIFS(Dissonance!$C$2:$C$57,"Critical feature",Dissonance!$I$2:$I$57,"KO") -> 0 | G17: =COUNTIFS(Dissonance!$C$2:$C$57,"Critical feature",Dissonance!$I$2:$I$57,"Blocked") -> 0 | H17: =COUNTIFS(Dissonance!$C$2:$C$57,"Critical feature",Dissonance!$I$2:$I$57,"N/A") -> 6 | I17: =IF(B17=0,0,(B17-C17)/B17) -> 1 | J17: =IF((B17-C17-H17)=0,"—",D17/(B17-C17-H17)) -> 1
A18: Pathly | B18: =COUNTIF(Pathly!$C$2:$C$37,"Critical feature") -> 26 | C18: =COUNTIFS(Pathly!$C$2:$C$37,"Critical feature",Pathly!$I$2:$I$37,"Not tested") -> 0 | D18: =COUNTIFS(Pathly!$C$2:$C$37,"Critical feature",Pathly!$I$2:$I$37,"OK") -> 23 | E18: =COUNTIFS(Pathly!$C$2:$C$37,"Critical feature",Pathly!$I$2:$I$37,"Partial") -> 2 | F18: =COUNTIFS(Pathly!$C$2:$C$37,"Critical feature",Pathly!$I$2:$I$37,"KO") -> 1 | G18: =COUNTIFS(Pathly!$C$2:$C$37,"Critical feature",Pathly!$I$2:$I$37,"Blocked") -> 0 | H18: =COUNTIFS(Pathly!$C$2:$C$37,"Critical feature",Pathly!$I$2:$I$37,"N/A") -> 0 | I18: =IF(B18=0,0,(B18-C18)/B18) -> 1 | J18: =IF((B18-C18-H18)=0,"—",D18/(B18-C18-H18)) -> 0.88461538
A19: Horus | B19: =COUNTIF(Horus!$C$2:$C$38,"Critical feature") -> 25 | C19: =COUNTIFS(Horus!$C$2:$C$38,"Critical feature",Horus!$I$2:$I$38,"Not tested") -> 0 | D19: =COUNTIFS(Horus!$C$2:$C$38,"Critical feature",Horus!$I$2:$I$38,"OK") -> 21 | E19: =COUNTIFS(Horus!$C$2:$C$38,"Critical feature",Horus!$I$2:$I$38,"Partial") -> 0 | F19: =COUNTIFS(Horus!$C$2:$C$38,"Critical feature",Horus!$I$2:$I$38,"KO") -> 4 | G19: =COUNTIFS(Horus!$C$2:$C$38,"Critical feature",Horus!$I$2:$I$38,"Blocked") -> 0 | H19: =COUNTIFS(Horus!$C$2:$C$38,"Critical feature",Horus!$I$2:$I$38,"N/A") -> 0 | I19: =IF(B19=0,0,(B19-C19)/B19) -> 1 | J19: =IF((B19-C19-H19)=0,"—",D19/(B19-C19-H19)) -> 0.84
A20: FAS | B20: =COUNTIF(FAS!$C$2:$C$45,"Critical feature") -> 19 | C20: =COUNTIFS(FAS!$C$2:$C$45,"Critical feature",FAS!$I$2:$I$45,"Not tested") -> 0 | D20: =COUNTIFS(FAS!$C$2:$C$45,"Critical feature",FAS!$I$2:$I$45,"OK") -> 13 | E20: =COUNTIFS(FAS!$C$2:$C$45,"Critical feature",FAS!$I$2:$I$45,"Partial") -> 2 | F20: =COUNTIFS(FAS!$C$2:$C$45,"Critical feature",FAS!$I$2:$I$45,"KO") -> 0 | G20: =COUNTIFS(FAS!$C$2:$C$45,"Critical feature",FAS!$I$2:$I$45,"Blocked") -> 0 | H20: =COUNTIFS(FAS!$C$2:$C$45,"Critical feature",FAS!$I$2:$I$45,"N/A") -> 4 | I20: =COUNTIFS(FAS!$C$2:$C$45,"Critical feature",FAS!$I$2:$I$45,"N/A") -> 4 | J20: =IF((B20-C20-H20)=0,"—",D20/(B20-C20-H20)) -> 0.86666667

Sheet Eclyps
A1: Feature ID | B1: Feature Name | C1: Category | D1: Dev status (team) | E1: Objective | F1: Prerequisites | G1: Steps | H1: Expected results | I1: RESULT | J1: Severity | K1: Feedback / anomaly (what you actually saw)
A2: F1 | B2: Install Game on PC | C2: Compatibility | D2: Done | E2: Verify that the game installs correctly on a Windows PC from the provided build. | F2: Game installer/build package available; sufficient disk space; Windows 10/11 PC | G2: 1. Download or copy the installer/build package to the target PC 2. Run the installer (or extract the build) 3. Follow the on-screen installation steps 4. Launch the game shortcut/executable once installation completes | H2: Installation completes without errors, and the game shortcut/executable is created and can be launched. | I2: OK
A3: F2 | B3: Launch the Game | C3: Critical feature | D3: Done | E3: Verify that the player can launch the game and reach the main menu. | F3: Game installed | G3: 1. Double-click the game executable/shortcut 2. Wait for the game to load 3. Observe the main menu | H3: The game launches without crashing and the main menu is displayed within a reasonable loading time. | I3: OK
A4: F3 | B4: Edit Graphics Settings | C4: User interface | D4: Done | E4: Verify that the player can change graphics quality settings. | F4: Game launched, Settings menu accessible | G4: 1. Open the Settings menu (M) 2. Go to the Graphics tab 3. Change the graphics quality preset (e.g. Low/Medium/High) 4. Apply/save changes 5. Return to gameplay | H4: The selected graphics quality is applied immediately or after confirmation, and the setting persists after restarting the game. | I4: OK | K4: could have a save button frowhe editing the controls
A5: F4 | B5: Edit Resolution Settings | C5: User interface | D5: Done | E5: Verify that the player can change the screen resolution. | F5: Game launched, Settings menu accessible | G5: 1. Open the Settings menu (M) 2. Go to the Display/Graphics tab 3. Select a different resolution from the list 4. Apply the change 5. Confirm the new resolution if a confirmation prompt appears | H5: The game switches to the selected resolution correctly, without distortion, and the change persists after restart. | I5: OK
A6: F5 | B6: Edit Keybinds | C6: User interface | D6: Done | E6: Verify that the player can remap keyboard/mouse keybinds. | F6: Game launched, Settings menu accessible | G6: 1. Open the Settings menu (M) 2. Go to the Controls/Keybinds tab 3. Select an action to rebind (e.g. "Change Gravity") 4. Press a new key 5. Save changes and return to gameplay 6. Test the action in-game with the new key | H6: The action is rebound to the new key, the old key no longer triggers it, and the new binding persists after restart. | I6: OK
A7: F6 | B7: Edit Volume Settings | C7: User interface | D7: Done | E7: Verify that the player can adjust audio volume levels. | F7: Game launched, Settings menu accessible | G7: 1. Open the Settings menu (M) 2. Go to the Audio tab 3. Adjust the master/music/SFX volume sliders 4. Apply changes 5. Return to gameplay and listen for the change | H7: In-game audio volume reflects the new slider values immediately, and the settings persist after restart. | I7: OK
A8: F7 | B8: Edit Mouse/Camera Sensitivity | C8: User interface | D8: Done | E8: Verify that the player can adjust camera/mouse sensitivity. | F8: Game launched, Settings menu accessible | G8: 1. Open the Settings menu (M) 2. Go to the Controls tab 3. Adjust the mouse/camera sensitivity slider 4. Apply changes 5. Return to gameplay and move the mouse to test camera speed | H8: Camera movement speed reflects the new sensitivity value, and the setting persists after restart. | I8: OK
A9: F8 | B9: Play with a Controller | C9: Compatibility | D9: Done | E9: Verify that the player can play the game using a controller. | F9: Compatible controller connected (wired or wireless) before or during launch | G9: 1. Connect a controller to the PC 2. Launch or resume the game 3. Move the character and camera using the controller sticks 4. Trigger core actions (interact, gravity change, menu navigation) using controller buttons | H9: The game detects the controller automatically, on-screen prompts switch to controller icons, and all core actions respond correctly to controller input. | I9: N/A | K9: i dont have a controller
A10: F9 | B10: Play with Keyboard & Mouse | C10: Compatibility | D10: Done | E10: Verify that the player can play the game using keyboard and mouse. | F10: Keyboard and mouse connected | G10: 1. Launch or resume the game with keyboard and mouse connected 2. Move the character using the keyboard 3. Look around using the mouse 4. Trigger core actions (interact (E), gravity change (G)) using keyboard/mouse inputs | H10: Character movement, camera look, and all core actions respond correctly to keyboard and mouse input, with on-screen prompts showing keyboard/mouse icons. | I10: OK
A11: F10 | B11: Change Gravity Manually | C11: Critical feature | D11: Done | E11: Verify that the player can change gravity direction using a dedicated key. | F11: Player in an open area with enough space to fall/land after a gravity change | G11: 1. Stand in an open area 2. Press the "Change Gravity" key (G) 3. Observe the character reorient and fall toward the new "down" direction 4. Repeat in a different direction | H11: Gravity direction changes instantly and consistently in the chosen direction, the character re-orients and falls correctly, with no clipping or getting stuck. | I11: OK
A12: F11 | B12: Trigger Gravity Change Through a Zone | C12: Critical feature | D12: Done | E12: Verify that gravity changes automatically when the player enters a designated trigger zone. | F12: Level section containing a gravity-trigger zone | G12: 1. Walk toward the trigger zone 2. Fully enter the zone 3. Observe gravity direction change automatically 4. Walk out of the zone and confirm gravity behavior afterward | H12: Gravity reorients automatically and smoothly as soon as the player enters the trigger zone, matching the zone's designated direction. | I12: OK
A13: F12 | B13: Run through Infinite Structure | C13: Critical feature | D13: Done | E13: Verify that the player can ascend or descend a staircase that loops infinitely. | F13: Level section containing the infinite stairs puzzle | G13: 1. Approach the character to interact with him (teleported to the stairs) 2. Walk up the stairs continuously for multiple flights 3. Walk down the stairs continuously for multiple flights 4. Observe the loop behavior and any visual cues | H13: The staircase loops seamlessly with no visible seams, loading hitches, or breaks in geometry while walking up or down. | I13: OK
A14: F13 | B14: Enter a Face of the Cube | C14: Critical feature | D14: Done | E14: Verify that the player can walk into a face of the non-euclidean cube and enter its interior space. | F14: Player standing next to the non-euclidean cube | G14: 1. Open the Level Menu with L keybind 2. Select the Cube Menu 3. Approach one face of the cube 4. Walk into the face 5. Observe the transition into the interior space | H14: The player enters the cube's interior smoothly, with a seamless transition and no camera clipping. | I14: OK
A15: F14 | B15: Resize Object via Forced Perspective | C15: Critical feature | D15: Done | E15: Verify that the player can change an object's apparent (and functional) size based on camera perspective. | F15: Level section containing a forced-perspective object | G15: 1. Target a holdable item with the crossair 2. Hold the left mouse button to pick it up 3. Look around to resize it (up for it to get bigger, down for smaller) 4. Pick up or release the object at the desired size | H15: The object's effective size updates according to the player's perspective, and the resized state is applied correctly when the illusion is "locked in". | I15: OK
A16: F15 | B16: Traverse a Seamless Portal | C16: Critical feature | D16: Done | E16: Verify that the player can walk through a portal and be seamlessly transported to the linked location. | F16: Level section containing a pair of linked portals | G16: 1. Approach the portal 2. See the other side (where you'll be teleported) through it 3. Walk through it 4. Observe the transition to the linked location 5. Confirm player position, velocity, and camera orientation after the transition | H16: The player is transported instantly and seamlessly, momentum and orientation are preserved correctly, with no loading pause or visual pop. | I16: OK
A17: F16 | B17: Save Game | C17: Critical feature | D17: Done | E17: Verify that the player can save game progress. | F17: Player has made progress in a level; save menu accessible | G17: 1. Open the pause/save menu (Through Main Menu accessed by M keybind) 2. Select "Save Game" 3. Choose a save slot (new or existing) 4. Confirm the save | H17: A confirmation message is shown, and a save file is created/updated with the player's current progress. | I17: OK
A18: F17 | B18: Load Game | C18: Critical feature | D18: Done | E18: Verify that the player can load a previously saved game. | F18: At least one save file exists | G18: 1. From the main menu or pause menu (M keybind), select "Load Game" 2. Choose a save slot 3. Confirm loading | H18: The game restores the player's exact saved state (position, inventory, level progress) without errors. | I18: OK
A19: F18 | B19: Interact with an Element | C19: Critical feature | D19: Done | E19: Verify that the player can interact with interactive objects in the environment. | F19: Level section containing multiple interactive objects (doors, switches, items) | G19: 1. Approach an interactive object 2. Hover the item to display interaction popup 3. Press the interact key/button indicated 4. Observe the resulting action | H19: Each interactive object responds correctly to the interact input (opens, activates, picked up, etc.) with no missed inputs. The instruction pop up should be displayed at step 2. | I19: Partial | K19: i can no clip on some parts of the house in lvl1 (the kitchen)
A20: F19 | B20: Reconstruct Projection into 3D Object | C20: Critical feature | D20: Done | E20: Verify that the player can turn a 2D wall projection into a real 3D object. | F20: A valid 2D projection is currently visible on a wall | G20: 1. Approach the 2D projection on the wall 2. Put yourself in the alignment of the projection to recompose the object 3. Observe the projection becoming a physical 3D object 4. Interact with the reconstructed item | H20: The 2D projection correctly converts into a solid, physically-present 3D object matching its projected shape. | I20: OK
A21: F20 | B21: Control the Day/Night Cycle | C21: Secondary function | D21: In progress | E21: Verify that the player can control the progression of the day/night cycle. | F21: Level section supporting the day/night cycle mechanic | G21: 1. Accelerate the day/night control (N) 2. Observe the lighting transition from day to night (or vice versa) 3. Confirm gameplay elements tied to the cycle react accordingly (not applicable yet) | H21: The lighting and sky transition smoothly between day and night when triggered, and the change is visually consistent across the scene. | I21: KO | K21: button doesnt work and cannot change it in the controls
A22: F21 | B22: Open & Close the Inventory | C22: User interface | D22: Done | E22: Verify that the player can open and close the inventory screen. | F22: Player has at least one item, or an empty inventory is accessible | G22: 1. Press the inventory key/button (I) 2. Observe the inventory screen opening 3. Press the key/button again to close it | H22: The inventory opens and closes smoothly without unexpectedly breaking other systems, and displays the correct current items. | I22: OK
A23: F22 | B23: Equip, Use and Combine Items | C23: Critical feature | D23: Done | E23: Verify that items picked up in the world are correctly added to the inventory. | F23: A pickupable item present in the level | G23: 1. Approach the plane piece in the barn 2. Press the interact/pick-up key (P) 3. Open the inventory and confirm the item appears 4) Drag the item and drop it in the first hotbar slot 5) Activate the hotbar slot pressing (1) 6) Equip item in hand using (W) 7) In the barn go close to the plane and press P to place (use) the item | H23: The item disappears from the world and appears correctly in the inventory with the correct icon/name. | I23: OK
A24: F23 | B24: Toggle Object Visibility | C24: Secondary function | D24: Done | E24: Verify that the player can toggle the visibility of certain objects using the visibility switch mechanic. | F24: Level section containing objects affected by the visibility switch | G24: 1. Go in a Visibility Zone (plateforms are in there) 2. Press E key to toggle on or off visiblity 3. Observe affected objects becoming visible or invisible 4. Toggle again and confirm objects revert | H24: Affected objects reliably switch between visible and invisible states, and their collision state updates consistently with their visibility (if intended). | I24: N/A | K24: could not access it
A25: F24 | B25: Crossing a Color Portal | C25: Secondary function | D25: Done | E25: Verify that the game's color grading evolves as intended (e.g. across levels or story progression). | F25: Progress through at least two areas/levels with different intended color styles | G25: 1. Approach a color portal 2.See the color changing through the portal 3. Cross the color portal 4. Observe the color grading change | H25: The color grading transitions smoothly and clearly reflects the intended visual evolution between areas or story beats. | I25: OK
A26: F25 | B26: View & Skip a Cinematic | C26: User interface | D26: Done | E26: Verify that story cinematics play correctly and return control to the player afterward. | F26: Level section that triggers a cinematic | G26: 1. Reach the trigger point for the cinematic by opening Showroom map 2. Let the cinematic play through fully 3. Confirm control returns to the player afterward 4. Repeat step 1 to 3 but hold Space to skip cinematic | H26: The cinematic plays without stutter or audio desync, and gameplay control is returned smoothly once it ends. | I26: N/A | K26: could not access it
A27: F26 | B27: Retry a Failed Puzzle Attempt | C27: Secondary function | D27: Done | E27: Verify that the player can retry a puzzle after an incorrect attempt without needing to restart the level. | F27: An incorrect combination/attempt has just been made on a puzzle | G27: 1. Attempt the puzzle and fail it 2. Observe the failure feedback 3. Attempt the puzzle again and win it to see the win condition | H27: The puzzle resets its interactive state after a failed attempt and can be immediately retried without a reload or crash. | I27: N/A | K27: could not access it
A28: F27 | B28: Activate a Pressure Plate | C28: Secondary function | D28: Done | E28: Verify that pressure plates correctly detect weight and trigger their linked mechanism. | F28: Level section containing a pressure plate and a linked mechanism (door, platform, etc.) | G28: 1. Step onto the pressure plate 2. Observe the linked mechanism activating (Door should open) 3. Step off the plate and observe whether the mechanism deactivates | H28: The pressure plate reliably detects the player and triggers the linked mechanism correctly each time. | I28: OK
A29: F28 | B29: Connect Cables (Snake-Style Mini-Game) | C29: Secondary function | D29: Done | E29: Verify that the player can complete the cable-connection mini-game to link two points. | F29: Level section containing a cable-connection puzzle | G29: 1. Interact with the cable puzzle to start it (E key) 2. Route the cable from the start point to the end point, avoiding obstacles (Navigating with movement keybinds) 3. Confirm the connection once the endpoint is reached | H29: The cable can be routed successfully to the endpoint, obstacles block invalid paths as intended, and a successful connection triggers the correct outcome. | I29: N/A | K29: could not access it
A30: F29 | B30: Switch to Third-Person Camera | C30: User interface | D30: Done | E30: Verify that the player can switch between first-person and third-person camera views. | F30: Player in an open area | G30: 1. Press the camera-toggle key/button (B) 2. Observe the camera switching to third-person 3. Move the character and camera to confirm normal behavior 4. Press B again to see the other point of view 4. Toggle back to first-person and confirm the switch (J) | H30: The camera switches cleanly between views with no clipping through the character or environment, and character control remains responsive in both modes. | I30: KO | K30: i cant toggle perspective
A31: F30 | B31: Capture Content with the Viewfinder | C31: Secondary function | D31: In progress | E31: Verify that the player can use the viewfinder to "capture" content from the game world. | F31: Level section supporting the viewfinder mechanic; a capturable object/scene in view | G31: 1. Take a picture with the camera item 2. Aim it at a capturable object or scene 3. Trigger the capture action 4. Confirm the captured content is stored (e.g. as a photo/item) | H31: The targeted content is correctly captured and stored, with clear visual/audio feedback confirming the capture. | I31: N/A | K31: Feature not implemented yet
A32: F31 | B32: Place the Photo Item into the Game | C32: Secondary function | D32: In progress | E32: Verify that previously captured photo content can be brought back into the game world as a real object. | F32: At least one piece of content has been captured with the viewfinder | G32: 1. Equip the photo Item in hand 2. Aim at a valid placement location 3. Trigger the placement action 4. Confirm the objects in the picture appears physically in the world | H32: The captured content materializes as a real, physically-present object at the targeted location, matching its captured appearance. | I32: N/A | K32: Feature not implemented yet
A33: F32 | B33: Interact with Tutorial Book | C33: User interface | D33: Not started | E33: Verify that the tutorial book teaches core controls correctly via its illustrated pages. | F33: Start of Chapter 1, player at the beginning of the bedroom scene | G33: 1. Approach the open book on the floor 2. Turn through its pages clicking next button 3. Observe the drawn control prompts (e.g. the stick-figure jumping on Space) 4. Close/put away the book once finished | H33: Each page displays the correct control prompt with a clear illustrated demonstration, and closing the book returns control to the player without issues. | I33: N/A | K33: Feature not implemented yet
A34: F33 | B34: Locate the Rocket Ship constellation | C34: Secondary function | D34: Not started | E34: Verify that looking through the telescope reveals the rocket-shaped constellation clue. | F34: Player is near the telescope in the bedroom | G34: 1. Interact with the telescope (E) to look through it 2. Observe the night sky view 3. Identify the rocket-shaped constellation | H34: The telescope view clearly displays a constellation shaped like the rocket, providing a legible clue toward the rocket toy. | I34: N/A | K34: Feature not implemented yet
A35: F34 | B35: Complete the "Find Jack" Enigma | C35: Critical feature | D35: Not started | E35: Verify that the player can complete the full "Find Jack" sequence from the locked door to retrieving the plushie. | F35: Player has explored the bedroom and identified the rocket toy as the point of interest | G35: 1. Attempt to open the bedroom door and observe it is locked 2. Enter the rocket toy by stepping through it's door 3. Observe the seamless transition into its giant imaginary interior 4. Complete the platformer section (bouncy plushie floor, moving platforms) to reach the top 5. Retrieve Jack, who is glowing at the top 6. Exit the rocket and observe it return to its small toy state 7. Open the now-unlocked bedroom door | H35: The entire sequence completes without errors: the transition into the rocket is seamless, the platformer section is completable without softlocks, Jack is correctly retrieved, and the door unlocks only after Jack is obtained. | I35: N/A | K35: Feature not implemented yet
A36: F35 | B36: Find Clothes Enigma | C36: Secondary function | D36: Not started | E36: Verify that the player can find and put on clothes before heading outside. | F36: Breakfast scene completed, mother has asked Céleste to get dressed | G36: 1. Explore the house to locate the clothes 2. Interact (E key) with the clothes to collect/equip them 3. Confirm Céleste is now dressed | H36: The clothes can be found through normal exploration, and once collected, the character model updates and the path outside becomes accessible. | I36: N/A | K36: Feature not implemented yet
A37: F36 | B37: Pilot the Plane during Flight Sequence | C37: Secondary function | D37: Not started | E37: Verify that the player can pilot the plane through the imaginary flight sequence. | F37: Plane repair puzzle completed, Céleste seated in the pilot's seat | G37: 1. Take control of the plane in the dream sequence 2. Steer to avoid obstacles 3. Fly through the luminous circles 4. Reach the end of the sequence | H37: The plane responds correctly to steering input, obstacles and circles register collisions/passes correctly, and the sequence ends cleanly back in reality. | I37: N/A | K37: Feature not implemented yet
A38: F37 | B38: Exit the Infinite Corridor Loop | C38: Critical feature | D38: Not started | E38: Verify that the hospital corridor loops infinitely when no valid exit condition has been met. | F38: Player is in the looping corridor segment, without the correct code/condition | G38: 1. Walk the corridor to its apparent end 2. Continue forward 3. Observe the corridor looping back to a previous or equivalent point 4. Repeat the loop at least twice 5. Spot a difference to break the loop 6. End the level by spotting the differences and escape all corridors | H38: The corridor loops seamlessly with no visible seam, loading hitch, or way to bypass it without meeting the exit condition. | I38: N/A | K38: Feature not implemented yet
A39: F38 | B39: Control the time | C39: Secondary function | D39: Not started | E39: Verify that the player can use directional movement to advance or rewind time in the maze, correctly moving objects around them. | F39: Player is in the Chapter 3 forest-approach maze sequence, following the star | G39: 1. Move in the "left" direction and observe time advancing (objects/obstacles shifting position accordingly) 2. Move in the opposite direction and observe time rewinding (objects/obstacles returning to prior positions) 3. Alternate directions to navigate around an obstacle that only allows passage at a specific point in time 4. Reach the end of the path using the time manipulation | H39: Moving in one direction consistently advances time and moving in the opposite direction consistently rewinds it, with surrounding objects updating position accordingly in both cases, and the maze is completable using this mechanic. | I39: N/A | K39: Feature not implemented yet
A40: F39 | B40: Request a Hint | C40: User interface | D40: Not started | E40: Verify that Jack the plushie provides hints, including prompting the player to use the day/night key. | F40: Player is in the forest with Jack equipped | G40: 1. Remain idle or stuck for a period 2. Observe Jack's hint behavior (glow/phosphorescence) 3. Observe the prompt suggesting the way to solve the enigma | H40: Jack's hint cues trigger appropriately without being intrusive, and the day/night key prompt is clear and correctly tied to the current situation. | I40: N/A | K40: Feature not implemented yet
...

Sheet Pathly
A1: Feature ID | B1: Feature Name | C1: Category | D1: Dev status (team) | E1: Objective | F1: Prerequisites | G1: Steps | H1: Expected results | I1: RESULT | J1: Severity | K1: Feedback / anomaly (what you actually saw)
A2: F1 | B2: Sign Up | C2: Critical feature | D2: Done | E2: Verify that a visitor can create two independent Pathly accounts for collaborative testing. | F2: Pathly is accessible from the Access link in the first tab. The tester has access to two different email addresses that are not already registered in Pathly. The optional temporary email service in the first tab may be used if appropriate. | G2: 1. Choose and note a unique Tester ID (for example AB4821) for this ATP run. 2. In a regular browser session, open the Pathly Access link and navigate to Sign up. 3. Create User A with a unique email address and a password chosen by the tester. 4. Complete any email/authentication verification requested and confirm that Pathly opens while authenticated. 5. Keep User A signed in. 6. Open a private/incognito window or a second browser and navigate to Sign up. 7. Create User B using a different unique email address and a password chosen by the tester. 8. Complete any verification requested and confirm that User B can access Pathly. 9. Keep both accounts available in their separate browser sessions for the following scenarios. | H2: Two distinct Pathly accounts are created without blocking errors. User A and User B can access the authenticated platform independently in separate browser sessions. | I2: OK
A3: F2 | B3: Log in and log out | C3: Critical feature | D3: Done | E3: Verify that an existing user can authenticate and securely end the session. | F3: User A and User B were created during F1. The tester knows the credentials for both accounts and has two separate browser sessions available. | G3: 1. Log out User A from the regular browser session. 2. Log in again using the User A credentials created during F1. 3. Confirm that the authenticated interface and sidebar are displayed. 4. Log out User B from the second/private browser session. 5. Log in again using the User B credentials created during F1. 6. Confirm that the authenticated interface is displayed for User B. 7. Leave User A and User B logged in in their separate sessions for the following scenarios. | H3: Both tester-created accounts can log out and authenticate again successfully, and each account remains isolated in its own browser session. | I3: OK
A4: F3 | B4: View and navigate trips from home | C4: Critical feature | D4: Done | E4: Verify that User A can view, search, filter and open their trips from Home. | F4: User A is logged in. Complete F4 first so that 'ATP Planned Trip - [Tester ID]' is available in User A's account. | G4: 1. Open Home as User A. 2. Verify the current/upcoming trip visualization. 3. Use the top-right view control to switch to the alternative trip list view. 4. Switch between Upcoming and Past trips. 5. Search for 'ATP Planned Trip - [Tester ID]'. 6. Use a trip card action shortcut such as Calendar, Chat, Files or Gallery. 7. Return to Home and open the trip by selecting its card. | H4: Trip views load correctly, filters and search update the displayed trips, card shortcuts open the expected section, and selecting a trip card opens the correct trip overview. | I4: Partial | J4: Minor | K4: Once you close the home sidebar, there's no way to open it again.
A5: F4 | B5: Create a planned trip | C5: Critical feature | D5: Done | E5: Verify that User A can create a trip when the destination and travel dates are already known. | F5: User A is logged in. A valid future date range and a cover image from the Test Files folder are available. A unique Tester ID was chosen in F1. | G5: 1. Open Create. 2. Select Planned Trip. 3. Enter the trip name 'ATP Planned Trip - [Tester ID]' using the Tester ID chosen in F1. 4. Set a destination such as Paris, France. 5. Select a valid future date range of at least 3 days. 6. Add a short description. 7. Continue to Friends & Cover and select/upload a cover image if requested. 8. Review the information. 9. Create the trip. 10. Return to Home and locate 'ATP Planned Trip - [Tester ID]'. | H5: The Planned Trip is created with the entered information, its overview opens successfully, and the trip remains visible from Home after a page reload. | I5: OK
A6: F5 | B6: Create an open trip | C6: Critical feature | D6: Done | E6: Verify that User A can create a trip whose destination and dates will be decided collaboratively. | F6: User A is logged in. A cover image from the Test Files folder is available. A unique Tester ID was chosen in F1. | G6: 1. Open Create. 2. Select Open Trip. 3. Enter the trip name 'ATP Open Trip - [Tester ID]' using the Tester ID chosen in F1, and add a short description. 4. Continue through the creation flow without selecting a final destination or travel dates. 5. Select/upload a cover image when requested. 6. Review the information. 7. Create the trip. | H6: The Open Trip is created and opens on the collaborative decision page where destinations and dates can be proposed and voted on. | I6: OK
A7: F6 | B7: Manage trip participants | C7: Critical feature | D7: Done | E7: Verify that the owner can invite another user and manage trip membership. | F7: User A and User B were created during F1 and are logged in in separate browser sessions. User A owns 'ATP Open Trip - [Tester ID]'. | G7: 1. As User A, open 'ATP Open Trip - [Tester ID]'. 2. Open the members/participants control. 3. Invite User B using the email/username of the User B account created during F1. 4. Switch to the separate User B browser session. 5. Open the trip invitation notification or invitation flow and accept/join the trip. 6. Return to User A and refresh the member list. 7. Verify that User B is listed as a member and that owner management controls are available. | H7: User B can join the trip and appears in the member list. User A retains the expected owner controls for trip participants. | I7: OK
A8: F7 | B8: Propose open trip destinations | C8: Critical feature | D8: Done | E8: Verify that trip members can submit destination proposals for an Open Trip. | F8: User A and User B are members of 'ATP Open Trip - [Tester ID]'. The trip is still in the destination/date decision stage. Use the same User A / User B pair created in F1 in separate browser sessions. | G8: 1. As User A, open 'ATP Open Trip - [Tester ID]'. 2. Select Propose destination. 3. Add 'Lisbon, Portugal'. 4. Add a second proposal such as 'Porto, Portugal'. 5. As User B, refresh/open the same trip. 6. Verify that both proposals are visible to both members. | H8: Both destination proposals are stored and displayed consistently to the trip members and are available for voting. | I8: OK
A9: F8 | B9: Propose open trip dates | C9: Critical feature | D9: Done | E9: Verify that trip members can submit possible travel date ranges for an Open Trip. | F9: User A and User B are members of 'ATP Open Trip - [Tester ID]'. The trip is still in the destination/date decision stage. Use the same User A / User B pair created in F1 in separate browser sessions. | G9: 1. Open 'ATP Open Trip - [Tester ID]'. 2. Select Propose dates. 3. Add a valid future date range of at least 3 days. 4. Add a second, different valid future date range. 5. Open the trip as the other user and refresh the page. 6. Verify that both proposed date ranges are visible. | H9: Both date proposals are stored, displayed to all trip members and available for voting. | I9: OK
A10: F9 | B10: Vote and finalize an open trip | C10: Critical feature | D10: Done | E10: Verify that members can vote on proposed destinations and dates and move the trip into the planning stage after reaching a shared decision. | F10: F7 and F8 have been completed. User A and User B are active members of 'ATP Open Trip - [Tester ID]' and can use separate sessions. | G10: 1. As User A, vote for 'Lisbon, Portugal' and one of the proposed date ranges. 2. As User B, vote for the same destination and date range. 3. Refresh both sessions and verify the winning destination/date information. 4. Complete any confirmation/acceptance required from both members. 5. Verify that the Start Planning action becomes available. 6. Start planning the trip. | H10: The selected destination and date range are reflected as the group decision and the Open Trip successfully transitions to the standard trip planning/overview state. | I10: OK
A11: F10 | B11: View trip overview | C11: Critical feature | D11: Done | E11: Verify that the trip overview displays the main planning information and provides access to the trip tools. | F11: ATP Open Trip - [Tester ID]' has been finalized through F9. User A is logged in. | G11: 1. Open 'ATP Open Trip - [Tester ID]' from Home. 2. Verify the trip title, description, destination, dates and participants. 3. Verify the planned activity count and trip progress area. 4. Verify the mini calendar. 5. Use the Chat, Expenses, Files and Gallery shortcuts and return to the overview after each check. 6. Select the mini calendar and verify that it opens the trip calendar. 7. Return to the overview. | H11: The overview shows the correct trip data and all displayed shortcuts navigate to the corresponding trip sections. | I11: OK
A12: F11 | B12: Edit trip information and visibility | C12: Critical feature | D12: Done | E12: Verify that a trip owner can edit trip properties and control public/private visibility. | F12: User A is logged in and owns 'ATP Planned Trip - [Tester ID]'. A test image is available from the Test Files folder. | G12: 1. Open 'ATP Planned Trip - [Tester ID]'. 2. Select Edit. 3. Modify the trip description. 4. Change the cover image if the edit flow allows it. 5. Save the changes. 6. Verify that the updated values are visible in the overview. 7. Use the visibility control over the cover image to make the itinerary Public. 8. Reload the page and verify that the public state is preserved. | H12: Edited trip information persists after reload and the trip can be changed to Public without a blocking error. | I12: OK
A13: F12 | B13: View and filter trip activities | C13: Critical feature | D13: Done | E13: Verify that trip members can access the complete activity list and filter activities by status. | F13: User A is logged in and 'ATP Open Trip - [Tester ID]' has been finalized. The trip contains at least two activities. If fewer than two activities exist, create simple temporary activities before continuing. | G13: 1. Open 'ATP Open Trip - [Tester ID]'. 2. Select All activities. 3. Verify that the activity cards display key information such as name, image, date/time, location, price and status when available. 4. Use the activity status filter. 5. Switch between at least two filter values. 6. Open one activity card. | H13: The list displays the trip activities, the selected filter changes the visible results correctly, and selecting a card opens the corresponding activity detail page. | I13: OK
A14: F13 | B14: Create an activity | C14: Critical feature | D14: Done | E14: Verify that a trip member can create a complete activity through the multi-step form. | F14: User A is logged in and is a member of 'ATP Open Trip - [Tester ID]'. The trip has finalized travel dates and the tester is using the Tester ID chosen in F1. | G14: 1. Open 'ATP Open Trip - [Tester ID]'. 2. Select Add activity. 3. Enter the name 'ATP Museum Visit - [Tester ID]'. 4. Add a description and at least one tag. 5. Complete the Details & Media step with optional price/media information. 6. Set a date within the trip date range, a valid time and a location. 7. Review the activity. 8. Create it. 9. Return to the activity list. | H14: The activity is created with the entered information, appears in 'ATP Open Trip - [Tester ID]', and remains available after reloading the page. | I14: OK
A15: F14 | B15: Create an activity from saved content | C15: Critical feature | D15: Done | E15: Verify that a saved public activity can be reused to pre-fill the activity creation form. | F15: User A is logged in. Public activities created by other users are available in Explore. 'ATP Planned Trip - [Tester ID]' exists. | G15: 1. Open Explore and select Activities. 2. Open any public activity and save it. 3. Note the saved activity title. 4. Open 'ATP Planned Trip - [Tester ID]'. 5. Select Add activity. 6. Select Use saved activity. 7. Choose the activity saved in step 2. 8. Verify that the creation form is pre-filled. 9. Adjust the date/time if necessary so it fits the trip. 10. Complete the creation flow. | H15: The saved activity can be selected, its information is used to pre-fill the form, and the new activity is successfully added to 'ATP Planned Trip - [Tester ID]'. | I15: OK
A16: F15 | B16: View and manage activity details | C16: Critical feature | D16: Done | E16: Verify that activity information can be viewed, edited, have its visibility changed, and be deleted when appropriate. | F16: ATP Museum Visit - [Tester ID]' exists in 'ATP Open Trip - [Tester ID]'. User A has permission to manage the activity. | G16: 1. Open the 'ATP Museum Visit - [Tester ID]' detail page. 2. Verify its description, date, time, location, price/tags and current status. 3. Select Edit, modify the description and save. 4. Verify that the edited description persists. 5. Toggle the activity visibility between Public and Private and verify the displayed state. 6. Create a temporary activity named 'ATP Delete Test - [Tester ID]' with the minimum required information. 7. Open 'ATP Delete Test - [Tester ID]'. 8. Select Delete and confirm the action. 9. Return to the activity list. | H16: Activity details are displayed correctly, edits and visibility changes persist, and the temporary activity is removed after deletion while 'ATP Museum Visit - [Tester ID]' remains available. | I16: OK
A17: F16 | B17: Vote on an activity | C17: Critical feature | D17: Done | E17: Verify that votes from multiple trip members are stored, displayed and can change the activity status. | F17: ATP Museum Visit - [Tester ID]' exists in 'ATP Open Trip - [Tester ID]' and is Pending. User A and User B are members of the trip and are open in separate browser sessions. | G17: 1. As User A, open 'ATP Museum Visit - [Tester ID]' and vote Accept. 2. As User B, open the same activity and vote Accept. 3. Refresh the activity in both sessions. 4. Verify that both participant votes are shown and that the activity reaches the expected accepted state. 5. Change User B's vote once and verify the update. 6. Change User B's vote back to Accept so the activity finishes accepted. | H17: Both users' votes are stored and visible, changing a vote updates the displayed result, and the final activity status reflects the participants' final votes. | I17: OK
A18: F17 | B18: Organize activities with the calendar | C18: Critical feature | D18: Done | E18: Verify the calendar views and activity rescheduling rules. | F18: ATP Open Trip - [Tester ID]' contains multiple activities. 'ATP Museum Visit - [Tester ID]' is accepted after F16 and at least one activity can be rescheduled. | G18: 1. Open the Calendar for 'ATP Open Trip - [Tester ID]'. 2. Switch between Day, Week and Month views. 3. Locate 'ATP Museum Visit - [Tester ID]'. 4. Drag the accepted activity to another valid date within the trip. 5. Confirm the move if requested. 6. Verify that moving the accepted activity resets its approval/votes and requires re-approval. 7. Move a Pending activity using drag and drop. 8. Reload the calendar. | H18: All calendar views load correctly, eligible activities can be moved to valid dates, the new dates persist after reload, and moving an accepted activity applies the documented vote-reset behavior. | I18: Partial | J18: Minor | K18: Dragging an activity in the day and week calendars work perfectly and as planed, but you can't drag an activity in the month format of the calendar
A19: F18 | B19: Use trip chat | C19: Critical feature | D19: Done | E19: Verify real-time trip communication between two participants. | F19: User A and User B are members of 'ATP Open Trip - [Tester ID]' and are logged in in separate browser sessions. | G19: 1. As User A, open Messages and select the 'ATP Open Trip - [Tester ID]' conversation. 2. Send the message 'ATP chat test - [Tester ID] - from User A'. 3. As User B, open the same trip conversation. 4. Verify that User A's message is visible. 5. Send the reply 'ATP chat test - [Tester ID] - from User B'. 6. Return to User A and verify that the reply is visible. 7. Use the Trip and Activities shortcuts at the top of the chat. | H19: Messages from both users are delivered to the correct trip conversation and the chat shortcuts open the related trip overview and activity list. | I19: OK
A20: F19 | B20: Share an activity in trip chat | C20: Secondary function | D20: Done | E20: Verify that an activity can be shared as a referenced item in the trip conversation. | F20: ATP Museum Visit - [Tester ID]' exists and 'ATP Open Trip - [Tester ID]' has an active conversation with User A and User B. Use the same User A / User B pair created in F1 in separate browser sessions. | G20: 1. As User A, open the 'ATP Museum Visit - [Tester ID]' detail page. 2. Select Send to chat. 3. Open the 'ATP Open Trip - [Tester ID]' conversation. 4. Verify that the activity reference appears in the chat. 5. Open the shared activity reference from the chat if it is clickable. 6. As User B, verify that the same shared item is visible. | H20: The activity is shared in the correct trip conversation as a recognizable referenced item and is visible to the trip participants. | I20: OK
A21: F20 | B21: Manage trip and activity files | C21: Critical feature | D21: Done | E21: Verify that files attached to an activity/trip can be accessed and downloaded. | F21: User A is logged in. 'ATP Open Trip - [Tester ID]' and 'ATP Museum Visit - [Tester ID]' exist. The Test Files to download link in the first tab contains 'test-file.pdf'. | G21: 1. Open the Test Files to download link from the first tab and download 'test-file.pdf'. 2. Open the 'ATP Museum Visit - [Tester ID]' detail page. 3. Open its Files section and attach 'test-file.pdf'. 4. Verify that the file is associated with the activity. 5. Open the trip-level Files page for 'ATP Open Trip - [Tester ID]'. 6. Locate the uploaded file. 7. Download the stored file from Pathly. | H21: The test PDF can be attached to the activity, is accessible from the relevant file views, and can be downloaded successfully from Pathly. | I21: KO | J21: Major | K21: You can't add files to trips
A22: F21 | B22: Manage trip gallery and activity photos | C22: Critical feature | D22: Done | E22: Verify that trip photos can be uploaded, viewed, filtered and downloaded, and that activity photos are accessible. | F22: User A is logged in. 'ATP Open Trip - [Tester ID]' exists. The Test Files to download link contains 'test-image'. | G22: 1. Download 'test-image' from the Test Files folder in the first tab. 2. Open the Gallery for 'ATP Open Trip - [Tester ID]'. 3. Select Upload and upload the test image. 4. Associate it with a trip day/activity if that option is presented. 5. Verify that the image appears in the gallery. 6. Use the day filter and verify that the image appears in the correct result. 7. Open the image viewer. 8. Verify the displayed day/activity metadata when available. 9. Download the image from the viewer. 10. Open the linked activity and verify its Photos section if the image was associated with an activity. | H22: The image uploads successfully, appears in the correct gallery context, responds to the day filter, opens in the viewer and can be downloaded. | I22: OK
A23: F22 | B23: Manage trip expenses | C23: Critical feature | D23: Done | E23: Verify that a shared expense can be recorded with payer and split information. | F23: User A and User B are the tester-created accounts from F1, are members of 'ATP Open Trip - [Tester ID]', and are open in separate browser sessions. The test PDF is available if a receipt is desired. | G23: 1. As User A, open Expenses for 'ATP Open Trip - [Tester ID]'. 2. Select US Dollar ($) as the expense currency if necessary. 3. Select Add expense. 4. Enter description 'ATP Dinner Expense - [Tester ID]' and total amount 50.00. 5. Optionally attach 'test-file.pdf' as the receipt. 6. Set User A as the person who paid. 7. Split the expense equally between User A and User B. 8. Save the expense. 9. Verify the new expense in the expense list. | H23: The 50.00 expense is recorded with User A as payer, is split equally between the two participants, and appears in the trip expense list with the correct information. | I23: OK
A24: F23 | B24: View balances and settle expenses | C24: Critical feature | D24: Done | E24: Verify that expense balances and pending settlements are calculated and can be marked as paid. | F24: F22 has been completed using the same tester-created User A / User B pair. 'ATP Dinner Expense - [Tester ID]' is 50.00, paid by User A and split equally between User A and User B. | G24: 1. Open Expenses after F22. 2. Verify Total expenses shows 50.00 in the selected currency. 3. Verify User B owes User A 25.00 and User A gets back 25.00. 4. In User B's session, open the same Expenses page. 5. Locate the pending settlement to User A. 6. Select Mark as paid. 7. Confirm the action if requested. 8. Refresh both sessions and review balances/settlements. | H24: Before settlement, the balances reflect the 25.00 debt correctly. After marking it as paid, the pending settlement is cleared or updated and the displayed balances reflect the settlement. | I24: OK
A25: F24 | B25: Explore public itineraries and activities | C25: Critical feature | D25: Done | E25: Verify that users can discover public travel content and switch between Explore content types/feeds. | F25: User B is logged in in its separate browser session. 'ATP Planned Trip - [Tester ID]' was made Public in F11 and User B is not a member of that trip. | G25: 1. As User B, open Explore. 2. Select the Discover feed. 3. Select Trips and search for 'ATP Planned Trip - [Tester ID]'. 4. Verify that the public trip card appears and displays its main information. 5. Switch to Activities and verify public activity cards are displayed. 6. Switch to the Following feed and verify that the feed changes without an error. 7. Return to Discover. | H25: Explore displays public trips and activities according to the selected content type/feed, and 'ATP Planned Trip - [Tester ID]' is discoverable by User B while public. | I25: OK
A26: F25 | B26: Search and discover people | C26: Secondary function | D26: Done | E26: Verify that a user can search another Pathly user by username and open the result profile. | F26: User A and User B are the two accounts created during F1. User B is the active account for this scenario. | G26: 1. In a User A session, open My Profile and note User A's Pathly username. 2. As User B, open Explore. 3. Select People. 4. Enter User A's username in the search field. 5. Select the matching result. | H26: User A is returned for the username search and selecting the result opens User A's public profile. | I26: OK
A27: F26 | B27: Interact with public content | C27: Secondary function | D27: Done | E27: Verify likes, comments, saves and sharing on another user's public content. | F27: User B is logged in and can access User A's public 'ATP Planned Trip - [Tester ID]' and its public activities. | G27: 1. Open 'ATP Planned Trip - [Tester ID]' as User B. 2. Like the itinerary. 3. Add the comment 'ATP public test comment - [Tester ID]'. 4. Save the itinerary. 5. Use Share and verify that a shareable link/action is produced. 6. Open a public activity and save it so it can be used in F29. 7. Open a different public activity, save it and then unsave it to verify both states. 8. Reload the public content. | H27: Like and comment states are reflected on the public content, the itinerary and selected activity remain saved after reload, unsaving removes the second item, and the Share action works without a blocking error. | I27: OK
